<?xml version="1.0" ?>
<!-- =================================================================================== -->
<!-- |    This document was autogenerated by xacro from ur5e_robot.urdf.xacro          | -->
<!-- |    EDITING THIS FILE BY HAND IS NOT RECOMMENDED                                 | -->
<!-- =================================================================================== -->
<robot name="atrv_ur5e" xmlns:xacro="http://ros.org/wiki/xacro">
  <!-- distance from robot center to wheel center in y direction (lateral direction) -->
  <!-- dummy link from which the real wheel will rotate from -->
  <link name="front_left_static">
    <inertial>
      <origin rpy="0 0 0" xyz="0 0 0"/>
      <mass value="0.01"/>
      <inertia ixx="0.0000288" ixy="0.0000001" ixz="0.000001" iyy="0.00004324" iyz="0.0000001" izz="0.0004130"/>
    </inertial>
  </link>
  <!-- to specify the position of the dummy link w.r.t. base link -->
  <joint name="front_left_static_joint" type="fixed">
    <parent link="teste2_link"/>
    <child link="front_left_static"/>
    <origin rpy="0 0 0" xyz="0.19 0.25 0.155"/>
  </joint>
  <!-- each wheel -->
  <link name="front_left_wheel_link">
    <visual>
      <origin rpy="1.570795 0 0" xyz="0 0 0"/>
      <geometry>
        <cylinder length="0.095" radius="0.155"/>
      </geometry>
      <material name="black"/>
    </visual>
    <collision>
      <origin rpy="1.570795 0 0" xyz="0 0 0"/>
      <geometry>
        <cylinder length="0.095" radius="0.155"/>
      </geometry>
    </collision>
    <inertial>
      <origin rpy="0 0 0" xyz="0 0 0"/>
      <mass value="5"/>
      <inertia ixx="0.021" ixy="0.0" ixz="0.0" iyy="0.04" iyz="0.0" izz="0.021"/>
    </inertial>
  </link>
  <!-- wheel joints -->
  <joint name="front_left_wheel" type="continuous">
    <parent link="front_left_static"/>
    <child link="front_left_wheel_link"/>
    <origin rpy="0 0 0" xyz="0 0 0"/>
    <axis xyz="0 1 0"/>
  </joint>
  <!-- to be able to rotate the wheels with a special plugin -->
  <transmission name="front_left_wheel_trans">
    <type>transmission_interface/SimpleTransmission</type>
    <joint name="front_left_wheel">
      <hardwareInterface>hardware_interface/VelocityJointInterface</hardwareInterface>
      <!-- talvez PositionJointInterface em vez de Velocity-->
    </joint>
    <actuator name="front_left_actuator">
      <mechanicalReduction>1</mechanicalReduction>
    </actuator>
  </transmission>
  <!-- dummy link from which the real wheel will rotate from -->
  <link name="front_right_static">
    <inertial>
      <origin rpy="0 0 0" xyz="0 0 0"/>
      <mass value="0.01"/>
      <inertia ixx="0.0000288" ixy="0.0000001" ixz="0.000001" iyy="0.00004324" iyz="0.0000001" izz="0.0004130"/>
    </inertial>
  </link>
  <!-- to specify the position of the dummy link w.r.t. base link -->
  <joint name="front_right_static_joint" type="fixed">
    <parent link="teste2_link"/>
    <child link="front_right_static"/>
    <origin rpy="0 0 0" xyz="0.19 -0.25 0.155"/>
  </joint>
  <!-- each wheel -->
  <link name="front_right_wheel_link">
    <visual>
      <origin rpy="1.570795 0 0" xyz="0 0 0"/>
      <geometry>
        <cylinder length="0.095" radius="0.155"/>
      </geometry>
      <material name="black"/>
    </visual>
    <collision>
      <origin rpy="1.570795 0 0" xyz="0 0 0"/>
      <geometry>
        <cylinder length="0.095" radius="0.155"/>
      </geometry>
    </collision>
    <inertial>
      <origin rpy="0 0 0" xyz="0 0 0"/>
      <mass value="5"/>
      <inertia ixx="0.021" ixy="0.0" ixz="0.0" iyy="0.04" iyz="0.0" izz="0.021"/>
    </inertial>
  </link>
  <!-- wheel joints -->
  <joint name="front_right_wheel" type="continuous">
    <parent link="front_right_static"/>
    <child link="front_right_wheel_link"/>
    <origin rpy="0 0 0" xyz="0 0 0"/>
    <axis xyz="0 1 0"/>
  </joint>
  <!-- to be able to rotate the wheels with a special plugin -->
  <transmission name="front_right_wheel_trans">
    <type>transmission_interface/SimpleTransmission</type>
    <joint name="front_right_wheel">
      <hardwareInterface>hardware_interface/VelocityJointInterface</hardwareInterface>
      <!-- talvez PositionJointInterface em vez de Velocity-->
    </joint>
    <actuator name="front_right_actuator">
      <mechanicalReduction>1</mechanicalReduction>
    </actuator>
  </transmission>
  <!-- dummy link from which the real wheel will rotate from -->
  <link name="rear_left_static">
    <inertial>
      <origin rpy="0 0 0" xyz="0 0 0"/>
      <mass value="0.01"/>
      <inertia ixx="0.0000288" ixy="0.0000001" ixz="0.000001" iyy="0.00004324" iyz="0.0000001" izz="0.0004130"/>
    </inertial>
  </link>
  <!-- to specify the position of the dummy link w.r.t. base link -->
  <joint name="rear_left_static_joint" type="fixed">
    <parent link="teste2_link"/>
    <child link="rear_left_static"/>
    <origin rpy="0 0 0" xyz="-0.19 0.25 0.155"/>
  </joint>
  <!-- each wheel -->
  <link name="rear_left_wheel_link">
    <visual>
      <origin rpy="1.570795 0 0" xyz="0 0 0"/>
      <geometry>
        <cylinder length="0.095" radius="0.155"/>
      </geometry>
      <material name="black"/>
    </visual>
    <collision>
      <origin rpy="1.570795 0 0" xyz="0 0 0"/>
      <geometry>
        <cylinder length="0.095" radius="0.155"/>
      </geometry>
    </collision>
    <inertial>
      <origin rpy="0 0 0" xyz="0 0 0"/>
      <mass value="5"/>
      <inertia ixx="0.021" ixy="0.0" ixz="0.0" iyy="0.04" iyz="0.0" izz="0.021"/>
    </inertial>
  </link>
  <!-- wheel joints -->
  <joint name="rear_left_wheel" type="continuous">
    <parent link="rear_left_static"/>
    <child link="rear_left_wheel_link"/>
    <origin rpy="0 0 0" xyz="0 0 0"/>
    <axis xyz="0 1 0"/>
  </joint>
  <!-- to be able to rotate the wheels with a special plugin -->
  <transmission name="rear_left_wheel_trans">
    <type>transmission_interface/SimpleTransmission</type>
    <joint name="rear_left_wheel">
      <hardwareInterface>hardware_interface/VelocityJointInterface</hardwareInterface>
      <!-- talvez PositionJointInterface em vez de Velocity-->
    </joint>
    <actuator name="rear_left_actuator">
      <mechanicalReduction>1</mechanicalReduction>
    </actuator>
  </transmission>
  <!-- dummy link from which the real wheel will rotate from -->
  <link name="rear_right_static">
    <inertial>
      <origin rpy="0 0 0" xyz="0 0 0"/>
      <mass value="0.01"/>
      <inertia ixx="0.0000288" ixy="0.0000001" ixz="0.000001" iyy="0.00004324" iyz="0.0000001" izz="0.0004130"/>
    </inertial>
  </link>
  <!-- to specify the position of the dummy link w.r.t. base link -->
  <joint name="rear_right_static_joint" type="fixed">
    <parent link="teste2_link"/>
    <child link="rear_right_static"/>
    <origin rpy="0 0 0" xyz="-0.19 -0.25 0.155"/>
  </joint>
  <!-- each wheel -->
  <link name="rear_right_wheel_link">
    <visual>
      <origin rpy="1.570795 0 0" xyz="0 0 0"/>
      <geometry>
        <cylinder length="0.095" radius="0.155"/>
      </geometry>
      <material name="black"/>
    </visual>
    <collision>
      <origin rpy="1.570795 0 0" xyz="0 0 0"/>
      <geometry>
        <cylinder length="0.095" radius="0.155"/>
      </geometry>
    </collision>
    <inertial>
      <origin rpy="0 0 0" xyz="0 0 0"/>
      <mass value="5"/>
      <inertia ixx="0.021" ixy="0.0" ixz="0.0" iyy="0.04" iyz="0.0" izz="0.021"/>
    </inertial>
  </link>
  <!-- wheel joints -->
  <joint name="rear_right_wheel" type="continuous">
    <parent link="rear_right_static"/>
    <child link="rear_right_wheel_link"/>
    <origin rpy="0 0 0" xyz="0 0 0"/>
    <axis xyz="0 1 0"/>
  </joint>
  <!-- to be able to rotate the wheels with a special plugin -->
  <transmission name="rear_right_wheel_trans">
    <type>transmission_interface/SimpleTransmission</type>
    <joint name="rear_right_wheel">
      <hardwareInterface>hardware_interface/VelocityJointInterface</hardwareInterface>
      <!-- talvez PositionJointInterface em vez de Velocity-->
    </joint>
    <actuator name="rear_right_actuator">
      <mechanicalReduction>1</mechanicalReduction>
    </actuator>
  </transmission>
  <link name="teste_link">
    <inertial>
      <origin rpy="0 0 0" xyz="0.0 0.0 0.0"/>
      <mass value="0.001"/>
      <inertia ixx="0.001" ixy="0.0" ixz="0.0" iyy="0.001" iyz="0.0" izz="0.001"/>
    </inertial>
  </link>
  <joint name="teste_joint" type="prismatic">
    <origin rpy="0 0 0" xyz="0 0 0"/>
    <parent link="base_link"/>
    <child link="teste_link"/>
    <axis xyz="1 0 0"/>
    <limit effort="80.0" lower="-2" upper="2" velocity="0.5"/>
  </joint>
  <link name="teste2_link">
    <collision>
      <origin rpy="0 0 0" xyz="0.0 0.0 0.3"/>
      <geometry>
        <box size="0.64 0.385 0.4"/>
      </geometry>
    </collision>
    <inertial>
      <origin rpy="0 0 0" xyz="0.0 0.0 0.0"/>
      <mass value="0.001"/>
      <inertia ixx="0.001" ixy="0.0" ixz="0.0" iyy="0.001" iyz="0.0" izz="0.001"/>
    </inertial>
  </link>
  <joint name="teste2_joint" type="prismatic">
    <origin rpy="0 0 0" xyz="0 0 0"/>
    <parent link="teste_link"/>
    <child link="teste2_link"/>
    <axis xyz="0 1 0"/>
    <limit effort="80.0" lower="-2" upper="2" velocity="0.5"/>
  </joint>
  <!-- links -->
  <!-- base_link -->
  <!-- The frame of the floor directly below the center_link and -->
  <!-- is needed for the navigation stack to work properly -->
  <link name="base_link">
    <inertial>
      <origin rpy="0 0 0" xyz="0.0 0.0 0.2"/>
      <mass value="50"/>
      <inertia ixx="2.01" ixy="0.0" ixz="0.0" iyy="2.51" iyz="0.0" izz="2.01"/>
    </inertial>
  </link>
  <!-- center_link -->
  <!-- The link that is the origin of all of the components of the -->
  <!-- robot and should also represent the main chassis via inertial, -->
  <!-- visual, and geometry elements of the link -->
  <link name="center_link">
    <visual>
      <geometry>
        <mesh filename="package://atrvjr_description/meshes/atrv_body.dae"/>
      </geometry>
    </visual>
  </link>
  <!-- base_link -> center_link -->
  <joint name="base_link_joint" type="fixed">
    <origin rpy="1.57 0 0" xyz="-0.1 0.19 0.0525"/>
    <parent link="teste2_link"/>
    <child link="center_link"/>
  </joint>
  <!-- Arm Link -->
  <link name="arm_base_frame"/>
  <joint name="$to_{armConnectionFrame}_joint" type="fixed">
    <origin rpy="0 0 0" xyz="0.12 0 0.56"/>
    <parent link="teste2_link"/>
    <child link="arm_base_frame"/>
  </joint>
  <!-- Crossbow Imu Link -->
  <link name="cbimu_frame"/>
  <joint name="base_cbimu_joint" type="fixed">
    <origin rpy="0 3.14159 0" xyz="0 0 0.267"/>
    <parent link="teste_link"/>
    <child link="cbimu_frame"/>
  </joint>
  <!-- MPU Imu Link -->
  <link name="mpuimu_frame"/>
  <joint name="base_mpuimu_joint" type="fixed">
    <origin rpy="0 0 1.570795" xyz="0 0 0.35"/>
    <parent link="teste_link"/>
    <child link="mpuimu_frame"/>
  </joint>
  <link name="novatel"/>
  <joint name="novatel_joint" type="fixed">
    <origin rpy="0 0 0" xyz="-0.15 0.1 0.4"/>
    <parent link="teste_link"/>
    <child link="novatel"/>
  </joint>
  <link name="hokuyo"/>
  <!--         <visual>
            <geometry>
                <box size="0.02 0.035 0.002"/>
            </geometry>
        </visual>
        <inertial>
            <mass value="0.001"/>
            <origin xyz="0 0 0"/>
            <inertia ixx="0.0001" ixy="0.0" ixz="0.0" iyy="0.0001" iyz="0.0" izz="0.0001"/>
        </inertial>
    </link> -->
  <joint name="laser_joint" type="fixed">
    <origin rpy="0 0 0" xyz="0.35 0 0.1"/>
    <parent link="teste_link"/>
    <child link="hokuyo"/>
  </joint>
  <transmission name="teste_prismatic_trans">
    <type>transmission_interface/SimpleTransmission</type>
    <joint name="teste_joint">
      <hardwareInterface>hardware_interface/VelocityJointInterface</hardwareInterface>
    </joint>
    <actuator name="teste_prismatic_actuator">
      <mechanicalReduction>1</mechanicalReduction>
    </actuator>
  </transmission>
  <transmission name="teste2_prismatic_trans">
    <type>transmission_interface/SimpleTransmission</type>
    <joint name="teste2_joint">
      <hardwareInterface>hardware_interface/VelocityJointInterface</hardwareInterface>
    </joint>
    <actuator name="teste2_prismatic_actuator">
      <mechanicalReduction>1</mechanicalReduction>
    </actuator>
  </transmission>
  <!--property name="shoulder_height" value="0.089159" /-->
  <!--property name="shoulder_offset" value="0.13585" /-->
  <!-- shoulder_offset - elbow_offset + wrist_1_length = 0.10915 -->
  <!--property name="upper_arm_length" value="0.42500" /-->
  <!--property name="elbow_offset" value="0.1197" /-->
  <!-- CAD measured -->
  <!--property name="forearm_length" value="0.39225" /-->
  <!--property name="wrist_1_length" value="0.093" /-->
  <!-- CAD measured -->
  <!--property name="wrist_2_length" value="0.09465" /-->
  <!-- In CAD this distance is 0.930, but in the spec it is 0.09465 -->
  <!--property name="wrist_3_length" value="0.0823" /-->
  <!-- manually measured -->
  <joint name="fixed_joint" type="fixed">
    <parent link="arm_base_frame"/>
    <child link="arm_base_link"/>
    <origin rpy="0.0 0.0 0.0" xyz="0.0 0.0 0.0"/>
  </joint>
  <link name="arm_base_link">
    <visual>
      <geometry>
        <mesh filename="package://ur_e_description/meshes/ur5e/visual/base.dae"/>
      </geometry>
      <material name="LightGrey">
        <color rgba="0.7 0.7 0.7 1.0"/>
      </material>
    </visual>
    <collision>
      <geometry>
        <mesh filename="package://ur_e_description/meshes/ur5e/collision/base.stl"/>
      </geometry>
    </collision>
    <inertial>
      <mass value="4.0"/>
      <origin rpy="0 0 0" xyz="0.0 0.0 0.0"/>
      <inertia ixx="0.00443333156" ixy="0.0" ixz="0.0" iyy="0.00443333156" iyz="0.0" izz="0.0072"/>
    </inertial>
  </link>
  <joint name="shoulder_pan_joint" type="revolute">
    <parent link="arm_base_link"/>
    <child link="shoulder_link"/>
    <origin rpy="0.0 0.0 0.0" xyz="0.0 0.0 0.163"/>
    <axis xyz="0 0 1"/>
    <limit effort="150.0" lower="-6.28318530718" upper="6.28318530718" velocity="3.14"/>
    <dynamics damping="0.0" friction="0.0"/>
  </joint>
  <link name="shoulder_link">
    <visual>
      <geometry>
        <mesh filename="package://ur_e_description/meshes/ur5e/visual/shoulder.dae"/>
      </geometry>
      <material name="LightGrey">
        <color rgba="0.7 0.7 0.7 1.0"/>
      </material>
    </visual>
    <collision>
      <geometry>
        <mesh filename="package://ur_e_description/meshes/ur5e/collision/shoulder.stl"/>
      </geometry>
    </collision>
    <inertial>
      <mass value="3.7"/>
      <origin rpy="0 0 0" xyz="0.0 0.0 0.0"/>
      <inertia ixx="0.010267495893" ixy="0.0" ixz="0.0" iyy="0.010267495893" iyz="0.0" izz="0.00666"/>
    </inertial>
  </link>
  <joint name="shoulder_lift_joint" type="revolute">
    <parent link="shoulder_link"/>
    <child link="upper_arm_link"/>
    <origin rpy="0.0 1.57079632679 0.0" xyz="0.0 0.138 0.0"/>
    <axis xyz="0 1 0"/>
    <limit effort="150.0" lower="-6.28318530718" upper="6.28318530718" velocity="3.14"/>
    <dynamics damping="0.0" friction="0.0"/>
  </joint>
  <link name="upper_arm_link">
    <visual>
      <geometry>
        <mesh filename="package://ur_e_description/meshes/ur5e/visual/upperarm.dae"/>
      </geometry>
      <material name="LightGrey">
        <color rgba="0.7 0.7 0.7 1.0"/>
      </material>
    </visual>
    <collision>
      <geometry>
        <mesh filename="package://ur_e_description/meshes/ur5e/collision/upperarm.stl"/>
      </geometry>
    </collision>
    <inertial>
      <mass value="8.393"/>
      <origin rpy="0 0 0" xyz="0.0 0.0 0.28"/>
      <inertia ixx="0.22689067591" ixy="0.0" ixz="0.0" iyy="0.22689067591" iyz="0.0" izz="0.0151074"/>
    </inertial>
  </link>
  <joint name="elbow_joint" type="revolute">
    <parent link="upper_arm_link"/>
    <child link="forearm_link"/>
    <origin rpy="0.0 0.0 0.0" xyz="0.0 -0.131 0.425"/>
    <axis xyz="0 1 0"/>
    <limit effort="150.0" lower="-3.14159265359" upper="3.14159265359" velocity="3.14"/>
    <dynamics damping="0.0" friction="0.0"/>
  </joint>
  <link name="forearm_link">
    <visual>
      <geometry>
        <mesh filename="package://ur_e_description/meshes/ur5e/visual/forearm.dae"/>
      </geometry>
      <material name="LightGrey">
        <color rgba="0.7 0.7 0.7 1.0"/>
      </material>
    </visual>
    <collision>
      <geometry>
        <mesh filename="package://ur_e_description/meshes/ur5e/collision/forearm.stl"/>
      </geometry>
    </collision>
    <inertial>
      <mass value="2.275"/>
      <origin rpy="0 0 0" xyz="0.0 0.0 0.25"/>
      <inertia ixx="0.049443313556" ixy="0.0" ixz="0.0" iyy="0.049443313556" iyz="0.0" izz="0.004095"/>
    </inertial>
  </link>
  <joint name="wrist_1_joint" type="revolute">
    <parent link="forearm_link"/>
    <child link="wrist_1_link"/>
    <origin rpy="0.0 1.57079632679 0.0" xyz="0.0 0.0 0.392"/>
    <axis xyz="0 1 0"/>
    <limit effort="28.0" lower="-6.28318530718" upper="6.28318530718" velocity="6.28"/>
    <dynamics damping="0.0" friction="0.0"/>
  </joint>
  <link name="wrist_1_link">
    <visual>
      <geometry>
        <mesh filename="package://ur_e_description/meshes/ur5e/visual/wrist1.dae"/>
      </geometry>
      <material name="LightGrey">
        <color rgba="0.7 0.7 0.7 1.0"/>
      </material>
    </visual>
    <collision>
      <geometry>
        <mesh filename="package://ur_e_description/meshes/ur5e/collision/wrist1.stl"/>
      </geometry>
    </collision>
    <inertial>
      <mass value="1.219"/>
      <origin rpy="0 0 0" xyz="0.0 0.0 0.0"/>
      <inertia ixx="0.111172755531" ixy="0.0" ixz="0.0" iyy="0.111172755531" iyz="0.0" izz="0.21942"/>
    </inertial>
  </link>
  <joint name="wrist_2_joint" type="revolute">
    <parent link="wrist_1_link"/>
    <child link="wrist_2_link"/>
    <origin rpy="0.0 0.0 0.0" xyz="0.0 0.127 0.0"/>
    <axis xyz="0 0 1"/>
    <limit effort="28.0" lower="-6.28318530718" upper="6.28318530718" velocity="6.28"/>
    <dynamics damping="0.0" friction="0.0"/>
  </joint>
  <link name="wrist_2_link">
    <visual>
      <geometry>
        <mesh filename="package://ur_e_description/meshes/ur5e/visual/wrist2.dae"/>
      </geometry>
      <material name="LightGrey">
        <color rgba="0.7 0.7 0.7 1.0"/>
      </material>
    </visual>
    <collision>
      <geometry>
        <mesh filename="package://ur_e_description/meshes/ur5e/collision/wrist2.stl"/>
      </geometry>
    </collision>
    <inertial>
      <mass value="1.219"/>
      <origin rpy="0 0 0" xyz="0.0 0.0 0.0"/>
      <inertia ixx="0.111172755531" ixy="0.0" ixz="0.0" iyy="0.111172755531" iyz="0.0" izz="0.21942"/>
    </inertial>
  </link>
  <joint name="wrist_3_joint" type="revolute">
    <parent link="wrist_2_link"/>
    <child link="wrist_3_link"/>
    <origin rpy="0.0 0.0 0.0" xyz="0.0 0.0 0.1"/>
    <axis xyz="0 1 0"/>
    <limit effort="28.0" lower="-6.28318530718" upper="6.28318530718" velocity="6.28"/>
    <dynamics damping="0.0" friction="0.0"/>
  </joint>
  <link name="wrist_3_link">
    <visual>
      <geometry>
        <mesh filename="package://ur_e_description/meshes/ur5e/visual/wrist3.dae"/>
      </geometry>
      <material name="LightGrey">
        <color rgba="0.7 0.7 0.7 1.0"/>
      </material>
    </visual>
    <collision>
      <geometry>
        <mesh filename="package://ur_e_description/meshes/ur5e/collision/wrist3.stl"/>
      </geometry>
    </collision>
    <inertial>
      <mass value="0.1879"/>
      <origin rpy="0 0 0" xyz="0.0 0.0 0.0"/>
      <inertia ixx="0.0171364731454" ixy="0.0" ixz="0.0" iyy="0.0171364731454" iyz="0.0" izz="0.033822"/>
    </inertial>
  </link>
  <joint name="ee_fixed_joint" type="fixed">
    <parent link="wrist_3_link"/>
    <child link="ee_link"/>
    <origin rpy="0.0 0.0 1.57079632679" xyz="0.0 0.1 0.0"/>
  </joint>
  <link name="ee_link">
    <collision>
      <geometry>
        <box size="0.01 0.01 0.01"/>
      </geometry>
      <origin rpy="0 0 0" xyz="-0.01 0 0"/>
    </collision>
  </link>
  <transmission name="shoulder_pan_trans">
    <type>transmission_interface/SimpleTransmission</type>
    <joint name="shoulder_pan_joint">
      <hardwareInterface>hardware_interface/VelocityJointInterface</hardwareInterface>
    </joint>
    <actuator name="shoulder_pan_motor">
      <mechanicalReduction>1</mechanicalReduction>
    </actuator>
  </transmission>
  <transmission name="shoulder_lift_trans">
    <type>transmission_interface/SimpleTransmission</type>
    <joint name="shoulder_lift_joint">
      <hardwareInterface>hardware_interface/VelocityJointInterface</hardwareInterface>
    </joint>
    <actuator name="shoulder_lift_motor">
      <mechanicalReduction>1</mechanicalReduction>
    </actuator>
  </transmission>
  <transmission name="elbow_trans">
    <type>transmission_interface/SimpleTransmission</type>
    <joint name="elbow_joint">
      <hardwareInterface>hardware_interface/VelocityJointInterface</hardwareInterface>
    </joint>
    <actuator name="elbow_motor">
      <mechanicalReduction>1</mechanicalReduction>
    </actuator>
  </transmission>
  <transmission name="wrist_1_trans">
    <type>transmission_interface/SimpleTransmission</type>
    <joint name="wrist_1_joint">
      <hardwareInterface>hardware_interface/VelocityJointInterface</hardwareInterface>
    </joint>
    <actuator name="wrist_1_motor">
      <mechanicalReduction>1</mechanicalReduction>
    </actuator>
  </transmission>
  <transmission name="wrist_2_trans">
    <type>transmission_interface/SimpleTransmission</type>
    <joint name="wrist_2_joint">
      <hardwareInterface>hardware_interface/VelocityJointInterface</hardwareInterface>
    </joint>
    <actuator name="wrist_2_motor">
      <mechanicalReduction>1</mechanicalReduction>
    </actuator>
  </transmission>
  <transmission name="wrist_3_trans">
    <type>transmission_interface/SimpleTransmission</type>
    <joint name="wrist_3_joint">
      <hardwareInterface>hardware_interface/VelocityJointInterface</hardwareInterface>
    </joint>
    <actuator name="wrist_3_motor">
      <mechanicalReduction>1</mechanicalReduction>
    </actuator>
  </transmission>
  <gazebo reference="shoulder_link">
    <selfCollide>true</selfCollide>
  </gazebo>
  <gazebo reference="upper_arm_link">
    <selfCollide>true</selfCollide>
  </gazebo>
  <gazebo reference="forearm_link">
    <selfCollide>true</selfCollide>
  </gazebo>
  <gazebo reference="wrist_1_link">
    <selfCollide>true</selfCollide>
  </gazebo>
  <gazebo reference="wrist_3_link">
    <selfCollide>true</selfCollide>
  </gazebo>
  <gazebo reference="wrist_2_link">
    <selfCollide>true</selfCollide>
  </gazebo>
  <gazebo reference="ee_link">
    <selfCollide>true</selfCollide>
  </gazebo>
  <!-- Frame coincident with all-zeros TCP on UR controller -->
  <link name="tool0"/>
  <joint name="wrist_3_link-tool0_fixed_joint" type="fixed">
    <origin rpy="-1.57079632679 0 0" xyz="0 0.1 0"/>
    <parent link="wrist_3_link"/>
    <child link="tool0"/>
  </joint>
  <material name="aluminum">
    <color rgba="0.5 0.5 0.5 1"/>
  </material>
  <!-- camera body, with origin at bottom screw mount -->
  <joint name="camera_joint" type="fixed">
    <!-- <xacro:insert_block name="origin" /> -->
    <origin rpy="0 0 0" xyz="0.2 0 0"/>
    <parent link="arm_base_link"/>
    <child link="camera_bottom_screw_frame"/>
  </joint>
  <link name="camera_bottom_screw_frame"/>
  <joint name="camera_link_joint" type="fixed">
    <origin rpy="0 0 0" xyz="0 0.0175 0.0125"/>
    <parent link="camera_bottom_screw_frame"/>
    <child link="camera_link"/>
  </joint>
  <link name="camera_link">
    <visual>
      <origin rpy="1.57079632679 0 1.57079632679" xyz="0.0149 -0.0175 0"/>
      <geometry>
        <!-- <box size="${d435_cam_width} ${d435_cam_height} ${d435_cam_depth}"/> -->
        <mesh filename="package://realsense2_camera/meshes/d435.dae"/>
        <!--<mesh filename="package://realsense2_camera/meshes/d435/d435.dae" />-->
      </geometry>
      <material name="aluminum"/>
    </visual>
    <collision>
      <origin rpy="0 0 0" xyz="0 -0.0175 0"/>
      <geometry>
        <box size="0.02505 0.09 0.025"/>
      </geometry>
    </collision>
    <inertial>
      <!-- The following are not reliable values, and should not be used for modeling -->
      <mass value="0.564"/>
      <origin xyz="0 0 0"/>
      <inertia ixx="0.003881243" ixy="0.0" ixz="0.0" iyy="0.000498940" iyz="0.0" izz="0.003879257"/>
    </inertial>
  </link>
  <!-- camera depth joints and links -->
  <joint name="camera_depth_joint" type="fixed">
    <origin rpy="0 0 0" xyz="0 0 0"/>
    <parent link="camera_link"/>
    <child link="camera_depth_frame"/>
  </joint>
  <link name="camera_depth_frame"/>
  <joint name="camera_depth_optical_joint" type="fixed">
    <origin rpy="-1.57079632679 0 -1.57079632679" xyz="0 0 0"/>
    <parent link="camera_depth_frame"/>
    <child link="camera_depth_optical_frame"/>
  </joint>
  <link name="camera_depth_optical_frame"/>
  <!-- camera left IR joints and links -->
  <joint name="camera_left_ir_joint" type="fixed">
    <origin rpy="0 0 0" xyz="0 0.0 0"/>
    <parent link="camera_depth_frame"/>
    <child link="camera_left_ir_frame"/>
  </joint>
  <link name="camera_left_ir_frame"/>
  <joint name="camera_left_ir_optical_joint" type="fixed">
    <origin rpy="-1.57079632679 0 -1.57079632679" xyz="0 0 0"/>
    <parent link="camera_left_ir_frame"/>
    <child link="camera_left_ir_optical_frame"/>
  </joint>
  <link name="camera_left_ir_optical_frame"/>
  <!-- camera right IR joints and links -->
  <joint name="camera_right_ir_joint" type="fixed">
    <origin rpy="0 0 0" xyz="0 -0.05 0"/>
    <parent link="camera_depth_frame"/>
    <child link="camera_right_ir_frame"/>
  </joint>
  <link name="camera_right_ir_frame"/>
  <joint name="camera_right_ir_optical_joint" type="fixed">
    <origin rpy="-1.57079632679 0 -1.57079632679" xyz="0 0 0"/>
    <parent link="camera_right_ir_frame"/>
    <child link="camera_right_ir_optical_frame"/>
  </joint>
  <link name="camera_right_ir_optical_frame"/>
  <!-- camera color joints and links -->
  <joint name="camera_color_joint" type="fixed">
    <origin rpy="0 0 0" xyz="0 0.015 0"/>
    <parent link="camera_depth_frame"/>
    <child link="camera_color_frame"/>
  </joint>
  <link name="camera_color_frame"/>
  <joint name="camera_color_optical_joint" type="fixed">
    <origin rpy="-1.57079632679 0 -1.57079632679" xyz="0 0 0"/>
    <parent link="camera_color_frame"/>
    <child link="camera_color_optical_frame"/>
  </joint>
  <link name="camera_color_optical_frame"/>
  <!-- 
  <link name="world" /> -->
  <!--  <joint name="world_joint" type="fixed">
    <parent link="world" />
    <child link = "base_link" />
    <origin xyz="0.0 0.0 0.0" rpy="0.0 0.0 0.0" />
  </joint> -->
</robot>

