<sdf version='1.6'>
  <world name='default'>
    <light name='sun' type='directional'>
      <cast_shadows>1</cast_shadows>
      <pose frame=''>0 0 10 0 -0 0</pose>
      <diffuse>0.8 0.8 0.8 1</diffuse>
      <specular>0.1 0.1 0.1 1</specular>
      <attenuation>
        <range>1000</range>
        <constant>0.9</constant>
        <linear>0.01</linear>
        <quadratic>0.001</quadratic>
      </attenuation>
      <direction>-0.5 0.5 -1</direction>
    </light>
    <model name='ground_plane'>
      <static>1</static>
      <link name='link'>
        <collision name='collision'>
          <geometry>
            <plane>
              <normal>0 0 1</normal>
              <size>100 100</size>
            </plane>
          </geometry>
          <surface>
            <friction>
              <ode>
                <mu>100</mu>
                <mu2>50</mu2>
              </ode>
              <torsional>
                <ode/>
              </torsional>
            </friction>
            <contact>
              <ode/>
            </contact>
            <bounce/>
          </surface>
          <max_contacts>10</max_contacts>
        </collision>
        <visual name='visual'>
          <cast_shadows>0</cast_shadows>
          <geometry>
            <plane>
              <normal>0 0 1</normal>
              <size>100 100</size>
            </plane>
          </geometry>
          <material>
            <script>
              <uri>file://media/materials/scripts/gazebo.material</uri>
              <name>Gazebo/Grey</name>
            </script>
          </material>
        </visual>
        <self_collide>0</self_collide>
        <kinematic>0</kinematic>
        <gravity>1</gravity>
      </link>
    </model>
    <gravity>0 0 -9.8</gravity>
    <magnetic_field>6e-06 2.3e-05 -4.2e-05</magnetic_field>
    <atmosphere type='adiabatic'/>
    <physics name='default_physics' default='0' type='ode'>
      <max_step_size>0.001</max_step_size>
      <real_time_factor>1</real_time_factor>
      <real_time_update_rate>1000</real_time_update_rate>
    </physics>
    <scene>
      <ambient>0.4 0.4 0.4 1</ambient>
      <background>0.7 0.7 0.7 1</background>
      <shadows>1</shadows>
    </scene>
    <spherical_coordinates>
      <surface_model>EARTH_WGS84</surface_model>
      <latitude_deg>0</latitude_deg>
      <longitude_deg>0</longitude_deg>
      <elevation>0</elevation>
      <heading_deg>0</heading_deg>
    </spherical_coordinates>
    <model name='robot'>
      <link name='base_link'>
        <pose frame=''>0 0 0 0 -0 0</pose>
        <inertial>
          <pose frame=''>0.001966 0 0.205868 0 -0 0</pose>
          <mass>61.04</mass>
          <inertia>
            <ixx>2.1413</ixx>
            <ixy>4e-07</ixy>
            <ixz>-0.0424918</ixz>
            <iyy>2.65447</iyy>
            <iyz>4e-07</iyz>
            <izz>2.03156</izz>
          </inertia>
        </inertial>
        <collision name='base_link_collision'>
          <pose frame=''>0 0 0.3 0 -0 0</pose>
          <geometry>
            <box>
              <size>0.64 0.385 0.4</size>
            </box>
          </geometry>
          <surface>
            <contact>
              <ode/>
            </contact>
            <friction>
              <ode/>
              <torsional>
                <ode/>
              </torsional>
            </friction>
            <bounce/>
          </surface>
          <max_contacts>10</max_contacts>
        </collision>
        <collision name='base_link_fixed_joint_lump__ur5_arm_base_link_collision_1'>
          <pose frame=''>0.12 0 0.56 0 -0 0</pose>
          <geometry>
            <mesh>
              <scale>1 1 1</scale>
              <uri>/home/mbzirc2020/atrv_ws/src/atrvjr_ur5/universal_robot/ur_description/meshes/ur5/collision/base.stl</uri>
            </mesh>
          </geometry>
          <max_contacts>10</max_contacts>
          <surface>
            <contact>
              <ode/>
            </contact>
            <bounce/>
            <friction>
              <torsional>
                <ode/>
              </torsional>
              <ode/>
            </friction>
          </surface>
        </collision>
        <visual name='base_link_fixed_joint_lump__ur5_arm_base_link_visual'>
          <pose frame=''>0.12 0 0.56 0 -0 0</pose>
          <geometry>
            <mesh>
              <scale>1 1 1</scale>
              <uri>/home/mbzirc2020/atrv_ws/src/atrvjr_ur5/universal_robot/ur_description/meshes/ur5/visual/base.dae</uri>
            </mesh>
          </geometry>
        </visual>
        <visual name='base_link_fixed_joint_lump__center_link_visual_1'>
          <pose frame=''>-0.1 0.19 0.0525 1.57 -0 0</pose>
          <geometry>
            <mesh>
              <scale>1 1 1</scale>
              <uri>/home/mbzirc2020/atrv_ws/src/atrvjr_ur5/atrvjr/description/atrvjr_description/meshes/atrv_body.dae</uri>
            </mesh>
          </geometry>
        </visual>
        <velocity_decay/>
        <gravity>1</gravity>
        <gravity>1</gravity>
        <velocity_decay/>
        <self_collide>0</self_collide>
        <sensor name='hokuyo_sensor' type='ray'>
          <visualize>1</visualize>
          <update_rate>34.5</update_rate>
          <ray>
            <scan>
              <horizontal>
                <samples>720</samples>
                <resolution>1</resolution>
                <min_angle>-1.5708</min_angle>
                <max_angle>1.5708</max_angle>
              </horizontal>
              <vertical>
                <samples>1</samples>
                <min_angle>0</min_angle>
                <max_angle>0</max_angle>
              </vertical>
            </scan>
            <range>
              <min>0.05</min>
              <max>20</max>
              <resolution>0.01</resolution>
            </range>
            <noise>
              <type>gaussian</type>
              <mean>0</mean>
              <stddev>0.01</stddev>
            </noise>
          </ray>
          <plugin name='gazebo_ros_hokuyo_controller' filename='libgazebo_ros_laser.so'>
            <topicName>/laser_scan</topicName>
            <frameName>hokuyo</frameName>
            <robotNamespace>/</robotNamespace>
          </plugin>
          <pose frame=''>0.35 0 0.25 0 -0 0</pose>
        </sensor>
        <kinematic>0</kinematic>
      </link>
      <link name='ur5_shoulder_link'>
        <pose frame=''>0.12 0 0.649159 0 -0 0</pose>
        <inertial>
          <pose frame=''>0 0 0 0 -0 0</pose>
          <mass>3.7</mass>
          <inertia>
            <ixx>0.0102675</ixx>
            <ixy>0</ixy>
            <ixz>0</ixz>
            <iyy>0.0102675</iyy>
            <iyz>0</iyz>
            <izz>0.00666</izz>
          </inertia>
        </inertial>
        <collision name='ur5_shoulder_link_collision'>
          <pose frame=''>0 0 0 0 -0 0</pose>
          <geometry>
            <mesh>
              <scale>1 1 1</scale>
              <uri>/home/mbzirc2020/atrv_ws/src/atrvjr_ur5/universal_robot/ur_description/meshes/ur5/collision/shoulder.stl</uri>
            </mesh>
          </geometry>
          <surface>
            <contact>
              <ode/>
            </contact>
            <friction>
              <ode/>
              <torsional>
                <ode/>
              </torsional>
            </friction>
            <bounce/>
          </surface>
          <max_contacts>10</max_contacts>
        </collision>
        <visual name='ur5_shoulder_link_visual'>
          <pose frame=''>0 0 0 0 -0 0</pose>
          <geometry>
            <mesh>
              <scale>1 1 1</scale>
              <uri>/home/mbzirc2020/atrv_ws/src/atrvjr_ur5/universal_robot/ur_description/meshes/ur5/visual/shoulder.dae</uri>
            </mesh>
          </geometry>
          <material>
            <script>
              <uri>__default__</uri>
              <name>__default__</name>
            </script>
          </material>
        </visual>
        <gravity>1</gravity>
        <velocity_decay/>
        <self_collide>1</self_collide>
        <kinematic>0</kinematic>
      </link>
      <joint name='ur5_shoulder_pan_joint' type='revolute'>
        <child>ur5_shoulder_link</child>
        <parent>base_link</parent>
        <axis>
          <xyz>0 0 1</xyz>
          <limit>
            <lower>-6.28319</lower>
            <upper>6.28319</upper>
            <effort>150</effort>
            <velocity>3.15</velocity>
          </limit>
          <dynamics>
            <damping>0</damping>
            <friction>0</friction>
            <spring_reference>0</spring_reference>
            <spring_stiffness>0</spring_stiffness>
          </dynamics>
          <use_parent_model_frame>1</use_parent_model_frame>
        </axis>
      </joint>
      <link name='ur5_upper_arm_link'>
        <pose frame=''>0.12 0.13585 0.649159 3.14159 1.57079 3.14159</pose>
        <inertial>
          <pose frame=''>0 0 0.28 0 -0 0</pose>
          <mass>8.393</mass>
          <inertia>
            <ixx>0.226891</ixx>
            <ixy>0</ixy>
            <ixz>0</ixz>
            <iyy>0.226891</iyy>
            <iyz>0</iyz>
            <izz>0.0151074</izz>
          </inertia>
        </inertial>
        <collision name='ur5_upper_arm_link_collision'>
          <pose frame=''>0 0 0 0 -0 0</pose>
          <geometry>
            <mesh>
              <scale>1 1 1</scale>
              <uri>/home/mbzirc2020/atrv_ws/src/atrvjr_ur5/universal_robot/ur_description/meshes/ur5/collision/upperarm.stl</uri>
            </mesh>
          </geometry>
          <surface>
            <contact>
              <ode/>
            </contact>
            <friction>
              <ode/>
              <torsional>
                <ode/>
              </torsional>
            </friction>
            <bounce/>
          </surface>
          <max_contacts>10</max_contacts>
        </collision>
        <visual name='ur5_upper_arm_link_visual'>
          <pose frame=''>0 0 0 0 -0 0</pose>
          <geometry>
            <mesh>
              <scale>1 1 1</scale>
              <uri>/home/mbzirc2020/atrv_ws/src/atrvjr_ur5/universal_robot/ur_description/meshes/ur5/visual/upperarm.dae</uri>
            </mesh>
          </geometry>
          <material>
            <script>
              <uri>__default__</uri>
              <name>__default__</name>
            </script>
          </material>
        </visual>
        <gravity>1</gravity>
        <velocity_decay/>
        <self_collide>1</self_collide>
        <kinematic>0</kinematic>
      </link>
      <joint name='ur5_shoulder_lift_joint' type='revolute'>
        <child>ur5_upper_arm_link</child>
        <parent>ur5_shoulder_link</parent>
        <axis>
          <xyz>0 1 0</xyz>
          <limit>
            <lower>-6.28319</lower>
            <upper>6.28319</upper>
            <effort>150</effort>
            <velocity>3.15</velocity>
          </limit>
          <dynamics>
            <damping>0</damping>
            <friction>0</friction>
            <spring_reference>0</spring_reference>
            <spring_stiffness>0</spring_stiffness>
          </dynamics>
          <use_parent_model_frame>1</use_parent_model_frame>
        </axis>
      </joint>
      <link name='ur5_forearm_link'>
        <pose frame=''>0.545 0.01615 0.649159 3.14159 1.57079 3.14159</pose>
        <inertial>
          <pose frame=''>0 0 0.25 0 -0 0</pose>
          <mass>2.275</mass>
          <inertia>
            <ixx>0.0494433</ixx>
            <ixy>0</ixy>
            <ixz>0</ixz>
            <iyy>0.0494433</iyy>
            <iyz>0</iyz>
            <izz>0.004095</izz>
          </inertia>
        </inertial>
        <collision name='ur5_forearm_link_collision'>
          <pose frame=''>0 0 0 0 -0 0</pose>
          <geometry>
            <mesh>
              <scale>1 1 1</scale>
              <uri>/home/mbzirc2020/atrv_ws/src/atrvjr_ur5/universal_robot/ur_description/meshes/ur5/collision/forearm.stl</uri>
            </mesh>
          </geometry>
          <surface>
            <contact>
              <ode/>
            </contact>
            <friction>
              <ode/>
              <torsional>
                <ode/>
              </torsional>
            </friction>
            <bounce/>
          </surface>
          <max_contacts>10</max_contacts>
        </collision>
        <visual name='ur5_forearm_link_visual'>
          <pose frame=''>0 0 0 0 -0 0</pose>
          <geometry>
            <mesh>
              <scale>1 1 1</scale>
              <uri>/home/mbzirc2020/atrv_ws/src/atrvjr_ur5/universal_robot/ur_description/meshes/ur5/visual/forearm.dae</uri>
            </mesh>
          </geometry>
          <material>
            <script>
              <uri>__default__</uri>
              <name>__default__</name>
            </script>
          </material>
        </visual>
        <gravity>1</gravity>
        <velocity_decay/>
        <self_collide>1</self_collide>
        <kinematic>0</kinematic>
      </link>
      <joint name='ur5_elbow_joint' type='revolute'>
        <child>ur5_forearm_link</child>
        <parent>ur5_upper_arm_link</parent>
        <axis>
          <xyz>0 1 0</xyz>
          <limit>
            <lower>-3.14159</lower>
            <upper>3.14159</upper>
            <effort>150</effort>
            <velocity>3.15</velocity>
          </limit>
          <dynamics>
            <damping>0</damping>
            <friction>0</friction>
            <spring_reference>0</spring_reference>
            <spring_stiffness>0</spring_stiffness>
          </dynamics>
          <use_parent_model_frame>1</use_parent_model_frame>
        </axis>
      </joint>
      <link name='ur5_wrist_1_link'>
        <pose frame=''>0.93725 0.01615 0.649159 3.14159 -0 3.14159</pose>
        <inertial>
          <pose frame=''>0 0 0 0 -0 0</pose>
          <mass>1.219</mass>
          <inertia>
            <ixx>0.0001</ixx>
            <ixy>0</ixy>
            <ixz>0</ixz>
            <iyy>0.0001</iyy>
            <iyz>0</iyz>
            <izz>0.0001</izz>
          </inertia>
        </inertial>
        <collision name='ur5_wrist_1_link_collision'>
          <pose frame=''>0 0 0 0 -0 0</pose>
          <geometry>
            <mesh>
              <scale>1 1 1</scale>
              <uri>/home/mbzirc2020/atrv_ws/src/atrvjr_ur5/universal_robot/ur_description/meshes/ur5/collision/wrist1.stl</uri>
            </mesh>
          </geometry>
          <surface>
            <contact>
              <ode/>
            </contact>
            <friction>
              <ode/>
              <torsional>
                <ode/>
              </torsional>
            </friction>
            <bounce/>
          </surface>
          <max_contacts>10</max_contacts>
        </collision>
        <visual name='ur5_wrist_1_link_visual'>
          <pose frame=''>0 0 0 0 -0 0</pose>
          <geometry>
            <mesh>
              <scale>1 1 1</scale>
              <uri>/home/mbzirc2020/atrv_ws/src/atrvjr_ur5/universal_robot/ur_description/meshes/ur5/visual/wrist1.dae</uri>
            </mesh>
          </geometry>
          <material>
            <script>
              <uri>__default__</uri>
              <name>__default__</name>
            </script>
          </material>
        </visual>
        <gravity>1</gravity>
        <velocity_decay/>
        <self_collide>1</self_collide>
        <kinematic>0</kinematic>
      </link>
      <joint name='ur5_wrist_1_joint' type='revolute'>
        <child>ur5_wrist_1_link</child>
        <parent>ur5_forearm_link</parent>
        <axis>
          <xyz>0 1 0</xyz>
          <limit>
            <lower>-6.28319</lower>
            <upper>6.28319</upper>
            <effort>28</effort>
            <velocity>3.2</velocity>
          </limit>
          <dynamics>
            <damping>0</damping>
            <friction>0</friction>
            <spring_reference>0</spring_reference>
            <spring_stiffness>0</spring_stiffness>
          </dynamics>
          <use_parent_model_frame>1</use_parent_model_frame>
        </axis>
      </joint>
      <link name='ur5_wrist_2_link'>
        <pose frame=''>0.93725 0.10915 0.649159 3.14159 -0 3.14159</pose>
        <inertial>
          <pose frame=''>0 0 0 0 -0 0</pose>
          <mass>1.219</mass>
          <inertia>
            <ixx>0.0001</ixx>
            <ixy>0</ixy>
            <ixz>0</ixz>
            <iyy>0.0001</iyy>
            <iyz>0</iyz>
            <izz>0.0001</izz>
          </inertia>
        </inertial>
        <collision name='ur5_wrist_2_link_collision'>
          <pose frame=''>0 0 0 0 -0 0</pose>
          <geometry>
            <mesh>
              <scale>1 1 1</scale>
              <uri>/home/mbzirc2020/atrv_ws/src/atrvjr_ur5/universal_robot/ur_description/meshes/ur5/collision/wrist2.stl</uri>
            </mesh>
          </geometry>
          <surface>
            <contact>
              <ode/>
            </contact>
            <friction>
              <ode/>
              <torsional>
                <ode/>
              </torsional>
            </friction>
            <bounce/>
          </surface>
          <max_contacts>10</max_contacts>
        </collision>
        <visual name='ur5_wrist_2_link_visual'>
          <pose frame=''>0 0 0 0 -0 0</pose>
          <geometry>
            <mesh>
              <scale>1 1 1</scale>
              <uri>/home/mbzirc2020/atrv_ws/src/atrvjr_ur5/universal_robot/ur_description/meshes/ur5/visual/wrist2.dae</uri>
            </mesh>
          </geometry>
          <material>
            <script>
              <uri>__default__</uri>
              <name>__default__</name>
            </script>
          </material>
        </visual>
        <gravity>1</gravity>
        <velocity_decay/>
        <self_collide>1</self_collide>
        <kinematic>0</kinematic>
      </link>
      <joint name='ur5_wrist_2_joint' type='revolute'>
        <child>ur5_wrist_2_link</child>
        <parent>ur5_wrist_1_link</parent>
        <axis>
          <xyz>0 0 -1</xyz>
          <limit>
            <lower>-6.28319</lower>
            <upper>6.28319</upper>
            <effort>28</effort>
            <velocity>3.2</velocity>
          </limit>
          <dynamics>
            <damping>0</damping>
            <friction>0</friction>
            <spring_reference>0</spring_reference>
            <spring_stiffness>0</spring_stiffness>
          </dynamics>
          <use_parent_model_frame>1</use_parent_model_frame>
        </axis>
      </joint>
      <link name='ur5_wrist_3_link'>
        <pose frame=''>0.93725 0.10915 0.554509 3.14159 -0 3.14159</pose>
        <inertial>
          <pose frame=''>0 0 0 0 -0 0</pose>
          <mass>0.1879</mass>
          <inertia>
            <ixx>0.0001</ixx>
            <ixy>0</ixy>
            <ixz>0</ixz>
            <iyy>0.0001</iyy>
            <iyz>0</iyz>
            <izz>0.0001</izz>
          </inertia>
        </inertial>
        <collision name='ur5_wrist_3_link_collision'>
          <pose frame=''>0 0 0 0 -0 0</pose>
          <geometry>
            <mesh>
              <scale>1 1 1</scale>
              <uri>/home/mbzirc2020/atrv_ws/src/atrvjr_ur5/universal_robot/ur_description/meshes/ur5/collision/wrist3.stl</uri>
            </mesh>
          </geometry>
          <surface>
            <contact>
              <ode/>
            </contact>
            <friction>
              <ode/>
              <torsional>
                <ode/>
              </torsional>
            </friction>
            <bounce/>
          </surface>
          <max_contacts>10</max_contacts>
        </collision>
        <collision name='ur5_wrist_3_link_fixed_joint_lump__ur5_ee_link_collision_1'>
          <pose frame=''>-0 0.0723 0 0 -0 1.5708</pose>
          <geometry>
            <box>
              <size>0.01 0.01 0.01</size>
            </box>
          </geometry>
          <surface>
            <contact>
              <ode/>
            </contact>
            <friction>
              <ode/>
              <torsional>
                <ode/>
              </torsional>
            </friction>
            <bounce/>
          </surface>
          <max_contacts>10</max_contacts>
        </collision>
        <visual name='ur5_wrist_3_link_visual'>
          <pose frame=''>0 0 0 0 -0 0</pose>
          <geometry>
            <mesh>
              <scale>1 1 1</scale>
              <uri>/home/mbzirc2020/atrv_ws/src/atrvjr_ur5/universal_robot/ur_description/meshes/ur5/visual/wrist3.dae</uri>
            </mesh>
          </geometry>
          <material>
            <script>
              <uri>__default__</uri>
              <name>__default__</name>
            </script>
          </material>
        </visual>
        <velocity_decay/>
        <gravity>1</gravity>
        <velocity_decay/>
        <self_collide>1</self_collide>
        <kinematic>0</kinematic>
      </link>
      <joint name='ur5_wrist_3_joint' type='revolute'>
        <child>ur5_wrist_3_link</child>
        <parent>ur5_wrist_2_link</parent>
        <axis>
          <xyz>0 1 0</xyz>
          <limit>
            <lower>-6.28319</lower>
            <upper>6.28319</upper>
            <effort>28</effort>
            <velocity>3.2</velocity>
          </limit>
          <dynamics>
            <damping>0</damping>
            <friction>0</friction>
            <spring_reference>0</spring_reference>
            <spring_stiffness>0</spring_stiffness>
          </dynamics>
          <use_parent_model_frame>1</use_parent_model_frame>
        </axis>
      </joint>
      <link name='front_left_wheel_link'>
        <pose frame=''>-0.19 0.25 0.155 0 -0 0</pose>
        <inertial>
          <pose frame=''>0 0 0 0 -0 0</pose>
          <mass>5</mass>
          <inertia>
            <ixx>0.021</ixx>
            <ixy>0</ixy>
            <ixz>0</ixz>
            <iyy>0.04</iyy>
            <iyz>0</iyz>
            <izz>0.021</izz>
          </inertia>
        </inertial>
        <collision name='front_left_wheel_link_collision'>
          <pose frame=''>0 0 0 1.57079 -0 0</pose>
          <geometry>
            <cylinder>
              <length>0.095</length>
              <radius>0.155</radius>
            </cylinder>
          </geometry>
          <surface>
            <contact>
              <ode/>
            </contact>
            <friction>
              <ode>
                <mu>0.1</mu>
                <mu2>0.1</mu2>
              </ode>
              <torsional>
                <ode/>
              </torsional>
            </friction>
            <bounce/>
          </surface>
          <max_contacts>10</max_contacts>
        </collision>
        <visual name='front_left_wheel_link_visual'>
          <pose frame=''>0 0 0 1.57079 -0 0</pose>
          <geometry>
            <cylinder>
              <length>0.095</length>
              <radius>0.155</radius>
            </cylinder>
          </geometry>
          <material>
            <script>
              <name>Gazebo/DarkGrey</name>
              <uri>file://media/materials/scripts/gazebo.material</uri>
            </script>
          </material>
        </visual>
        <gravity>1</gravity>
        <velocity_decay/>
        <self_collide>0</self_collide>
        <kinematic>0</kinematic>
      </link>
      <joint name='front_left_wheel' type='revolute'>
        <child>front_left_wheel_link</child>
        <parent>base_link</parent>
        <axis>
          <xyz>0 1 0</xyz>
          <limit>
            <lower>-1e+16</lower>
            <upper>1e+16</upper>
          </limit>
          <dynamics>
            <spring_reference>0</spring_reference>
            <spring_stiffness>0</spring_stiffness>
          </dynamics>
          <use_parent_model_frame>1</use_parent_model_frame>
        </axis>
      </joint>
      <link name='front_right_wheel_link'>
        <pose frame=''>0.19 0.25 0.155 0 -0 0</pose>
        <inertial>
          <pose frame=''>0 0 0 0 -0 0</pose>
          <mass>5</mass>
          <inertia>
            <ixx>0.021</ixx>
            <ixy>0</ixy>
            <ixz>0</ixz>
            <iyy>0.04</iyy>
            <iyz>0</iyz>
            <izz>0.021</izz>
          </inertia>
        </inertial>
        <collision name='front_right_wheel_link_collision'>
          <pose frame=''>0 0 0 1.57079 -0 0</pose>
          <geometry>
            <cylinder>
              <length>0.095</length>
              <radius>0.155</radius>
            </cylinder>
          </geometry>
          <surface>
            <contact>
              <ode/>
            </contact>
            <friction>
              <ode>
                <mu>0.1</mu>
                <mu2>0.1</mu2>
              </ode>
              <torsional>
                <ode/>
              </torsional>
            </friction>
            <bounce/>
          </surface>
          <max_contacts>10</max_contacts>
        </collision>
        <visual name='front_right_wheel_link_visual'>
          <pose frame=''>0 0 0 1.57079 -0 0</pose>
          <geometry>
            <cylinder>
              <length>0.095</length>
              <radius>0.155</radius>
            </cylinder>
          </geometry>
          <material>
            <script>
              <name>Gazebo/DarkGrey</name>
              <uri>file://media/materials/scripts/gazebo.material</uri>
            </script>
          </material>
        </visual>
        <gravity>1</gravity>
        <velocity_decay/>
        <self_collide>0</self_collide>
        <kinematic>0</kinematic>
      </link>
      <joint name='front_right_wheel' type='revolute'>
        <child>front_right_wheel_link</child>
        <parent>base_link</parent>
        <axis>
          <xyz>0 1 0</xyz>
          <limit>
            <lower>-1e+16</lower>
            <upper>1e+16</upper>
          </limit>
          <dynamics>
            <spring_reference>0</spring_reference>
            <spring_stiffness>0</spring_stiffness>
          </dynamics>
          <use_parent_model_frame>1</use_parent_model_frame>
        </axis>
      </joint>
      <link name='rear_left_wheel_link'>
        <pose frame=''>-0.19 -0.25 0.155 0 -0 0</pose>
        <inertial>
          <pose frame=''>0 0 0 0 -0 0</pose>
          <mass>5</mass>
          <inertia>
            <ixx>0.021</ixx>
            <ixy>0</ixy>
            <ixz>0</ixz>
            <iyy>0.04</iyy>
            <iyz>0</iyz>
            <izz>0.021</izz>
          </inertia>
        </inertial>
        <collision name='rear_left_wheel_link_collision'>
          <pose frame=''>0 0 0 1.57079 -0 0</pose>
          <geometry>
            <cylinder>
              <length>0.095</length>
              <radius>0.155</radius>
            </cylinder>
          </geometry>
          <surface>
            <contact>
              <ode/>
            </contact>
            <friction>
              <ode>
                <mu>0.1</mu>
                <mu2>0.1</mu2>
              </ode>
              <torsional>
                <ode/>
              </torsional>
            </friction>
            <bounce/>
          </surface>
          <max_contacts>10</max_contacts>
        </collision>
        <visual name='rear_left_wheel_link_visual'>
          <pose frame=''>0 0 0 1.57079 -0 0</pose>
          <geometry>
            <cylinder>
              <length>0.095</length>
              <radius>0.155</radius>
            </cylinder>
          </geometry>
          <material>
            <script>
              <name>Gazebo/DarkGrey</name>
              <uri>file://media/materials/scripts/gazebo.material</uri>
            </script>
          </material>
        </visual>
        <gravity>1</gravity>
        <velocity_decay/>
        <self_collide>0</self_collide>
        <kinematic>0</kinematic>
      </link>
      <joint name='rear_left_wheel' type='revolute'>
        <child>rear_left_wheel_link</child>
        <parent>base_link</parent>
        <axis>
          <xyz>0 1 0</xyz>
          <limit>
            <lower>-1e+16</lower>
            <upper>1e+16</upper>
          </limit>
          <dynamics>
            <spring_reference>0</spring_reference>
            <spring_stiffness>0</spring_stiffness>
          </dynamics>
          <use_parent_model_frame>1</use_parent_model_frame>
        </axis>
      </joint>
      <link name='rear_right_wheel_link'>
        <pose frame=''>0.19 -0.25 0.155 0 -0 0</pose>
        <inertial>
          <pose frame=''>0 0 0 0 -0 0</pose>
          <mass>5</mass>
          <inertia>
            <ixx>0.021</ixx>
            <ixy>0</ixy>
            <ixz>0</ixz>
            <iyy>0.04</iyy>
            <iyz>0</iyz>
            <izz>0.021</izz>
          </inertia>
        </inertial>
        <collision name='rear_right_wheel_link_collision'>
          <pose frame=''>0 0 0 1.57079 -0 0</pose>
          <geometry>
            <cylinder>
              <length>0.095</length>
              <radius>0.155</radius>
            </cylinder>
          </geometry>
          <surface>
            <contact>
              <ode/>
            </contact>
            <friction>
              <ode>
                <mu>0.1</mu>
                <mu2>0.1</mu2>
              </ode>
              <torsional>
                <ode/>
              </torsional>
            </friction>
            <bounce/>
          </surface>
          <max_contacts>10</max_contacts>
        </collision>
        <visual name='rear_right_wheel_link_visual'>
          <pose frame=''>0 0 0 1.57079 -0 0</pose>
          <geometry>
            <cylinder>
              <length>0.095</length>
              <radius>0.155</radius>
            </cylinder>
          </geometry>
          <material>
            <script>
              <name>Gazebo/DarkGrey</name>
              <uri>file://media/materials/scripts/gazebo.material</uri>
            </script>
          </material>
        </visual>
        <gravity>1</gravity>
        <velocity_decay/>
        <self_collide>0</self_collide>
        <kinematic>0</kinematic>
      </link>
      <joint name='rear_right_wheel' type='revolute'>
        <child>rear_right_wheel_link</child>
        <parent>base_link</parent>
        <axis>
          <xyz>0 1 0</xyz>
          <limit>
            <lower>-1e+16</lower>
            <upper>1e+16</upper>
          </limit>
          <dynamics>
            <spring_reference>0</spring_reference>
            <spring_stiffness>0</spring_stiffness>
          </dynamics>
          <use_parent_model_frame>1</use_parent_model_frame>
        </axis>
      </joint>
      <static>0</static>
      <plugin name='ros_control' filename='libgazebo_ros_control.so'>
        <robotNamespace>/</robotNamespace>
        <robotSimType>gazebo_ros_control/DefaultRobotHWSim</robotSimType>
        <legacyModeNS>true</legacyModeNS>
      </plugin>
      <pose frame=''>0 0 0.1 0 -0 0</pose>
    </model>
    <model name='unit_box_0'>
      <pose frame=''>2.80492 -0.080136 0.5 0 -0 0</pose>
      <link name='link'>
        <inertial>
          <mass>1</mass>
          <inertia>
            <ixx>0.166667</ixx>
            <ixy>0</ixy>
            <ixz>0</ixz>
            <iyy>0.166667</iyy>
            <iyz>0</iyz>
            <izz>0.166667</izz>
          </inertia>
        </inertial>
        <collision name='collision'>
          <geometry>
            <box>
              <size>1 1 1</size>
            </box>
          </geometry>
          <max_contacts>10</max_contacts>
          <surface>
            <contact>
              <ode/>
            </contact>
            <bounce/>
            <friction>
              <torsional>
                <ode/>
              </torsional>
              <ode/>
            </friction>
          </surface>
        </collision>
        <visual name='visual'>
          <geometry>
            <box>
              <size>1 1 1</size>
            </box>
          </geometry>
          <material>
            <script>
              <name>Gazebo/Grey</name>
              <uri>file://media/materials/scripts/gazebo.material</uri>
            </script>
          </material>
        </visual>
        <self_collide>0</self_collide>
        <kinematic>0</kinematic>
        <gravity>1</gravity>
      </link>
    </model>
    <model name='unit_box_1'>
      <pose frame=''>5.55277 2.33485 0.5 0 -0 0</pose>
      <link name='link'>
        <inertial>
          <mass>1</mass>
          <inertia>
            <ixx>0.166667</ixx>
            <ixy>0</ixy>
            <ixz>0</ixz>
            <iyy>0.166667</iyy>
            <iyz>0</iyz>
            <izz>0.166667</izz>
          </inertia>
        </inertial>
        <collision name='collision'>
          <geometry>
            <box>
              <size>1 1 1</size>
            </box>
          </geometry>
          <max_contacts>10</max_contacts>
          <surface>
            <contact>
              <ode/>
            </contact>
            <bounce/>
            <friction>
              <torsional>
                <ode/>
              </torsional>
              <ode/>
            </friction>
          </surface>
        </collision>
        <visual name='visual'>
          <geometry>
            <box>
              <size>1 1 1</size>
            </box>
          </geometry>
          <material>
            <script>
              <name>Gazebo/Grey</name>
              <uri>file://media/materials/scripts/gazebo.material</uri>
            </script>
          </material>
        </visual>
        <self_collide>0</self_collide>
        <kinematic>0</kinematic>
        <gravity>1</gravity>
      </link>
    </model>
    <model name='unit_box_2'>
      <pose frame=''>5.45209 -2.77816 0.5 0 -0 0</pose>
      <link name='link'>
        <inertial>
          <mass>1</mass>
          <inertia>
            <ixx>0.166667</ixx>
            <ixy>0</ixy>
            <ixz>0</ixz>
            <iyy>0.166667</iyy>
            <iyz>0</iyz>
            <izz>0.166667</izz>
          </inertia>
        </inertial>
        <collision name='collision'>
          <geometry>
            <box>
              <size>1 1 1</size>
            </box>
          </geometry>
          <max_contacts>10</max_contacts>
          <surface>
            <contact>
              <ode/>
            </contact>
            <bounce/>
            <friction>
              <torsional>
                <ode/>
              </torsional>
              <ode/>
            </friction>
          </surface>
        </collision>
        <visual name='visual'>
          <geometry>
            <box>
              <size>1 1 1</size>
            </box>
          </geometry>
          <material>
            <script>
              <name>Gazebo/Grey</name>
              <uri>file://media/materials/scripts/gazebo.material</uri>
            </script>
          </material>
        </visual>
        <self_collide>0</self_collide>
        <kinematic>0</kinematic>
        <gravity>1</gravity>
      </link>
    </model>
    <model name='unit_box_3'>
      <pose frame=''>6.48527 -1.38379 0.5 0 -0 0</pose>
      <link name='link'>
        <inertial>
          <mass>1</mass>
          <inertia>
            <ixx>0.166667</ixx>
            <ixy>0</ixy>
            <ixz>0</ixz>
            <iyy>0.166667</iyy>
            <iyz>0</iyz>
            <izz>0.166667</izz>
          </inertia>
        </inertial>
        <collision name='collision'>
          <geometry>
            <box>
              <size>1 1 1</size>
            </box>
          </geometry>
          <max_contacts>10</max_contacts>
          <surface>
            <contact>
              <ode/>
            </contact>
            <bounce/>
            <friction>
              <torsional>
                <ode/>
              </torsional>
              <ode/>
            </friction>
          </surface>
        </collision>
        <visual name='visual'>
          <geometry>
            <box>
              <size>1 1 1</size>
            </box>
          </geometry>
          <material>
            <script>
              <name>Gazebo/Grey</name>
              <uri>file://media/materials/scripts/gazebo.material</uri>
            </script>
          </material>
        </visual>
        <self_collide>0</self_collide>
        <kinematic>0</kinematic>
        <gravity>1</gravity>
      </link>
    </model>
    <state world_name='default'>
      <sim_time>313 512000000</sim_time>
      <real_time>386 624061111</real_time>
      <wall_time>1551973610 235319454</wall_time>
      <iterations>313512</iterations>
      <model name='ground_plane'>
        <pose frame=''>0 0 0 0 -0 0</pose>
        <scale>1 1 1</scale>
        <link name='link'>
          <pose frame=''>0 0 0 0 -0 0</pose>
          <velocity>0 0 0 0 -0 0</velocity>
          <acceleration>0 0 0 0 -0 0</acceleration>
          <wrench>0 0 0 0 -0 0</wrench>
        </link>
      </model>
      <model name='robot'>
        <pose frame=''>-0.129626 -0.067578 -2e-06 -2.1e-05 2.8e-05 0.022931</pose>
        <scale>1 1 1</scale>
        <link name='base_link'>
          <pose frame=''>-0.129626 -0.067578 -2e-06 -2.1e-05 2.8e-05 0.022931</pose>
          <velocity>-0.001128 -0.007681 -0.001891 -0.032477 0.004661 0.000289</velocity>
          <acceleration>0.055191 0.316046 -1.67332 0.754508 0.902295 2.89976</acceleration>
          <wrench>3.36889 19.2914 -102.139 0 -0 0</wrench>
        </link>
        <link name='front_left_wheel_link'>
          <pose frame=''>-0.325304 0.178004 0.154998 -1.9e-05 -0.126269 0.022935</pose>
          <velocity>-0.000481 -0.002766 -0.008939 -0.03316 0.004321 7.1e-05</velocity>
          <acceleration>0.564583 -2.02799 -15.1464 0.486829 1.29207 -3.06275</acceleration>
          <wrench>2.82291 -10.1399 -75.732 0 -0 0</wrench>
        </link>
        <link name='front_right_wheel_link'>
          <pose frame=''>0.054596 0.186716 0.154989 -3.1e-05 -0.064049 0.022937</pose>
          <velocity>-0.000517 -0.002386 -0.011357 -0.030315 0.00439 -0.000541</velocity>
          <acceleration>0.564801 -2.04899 -11.8582 -2.59305 0.928649 -2.57668</acceleration>
          <wrench>2.824 -10.245 -59.2912 0 -0 0</wrench>
        </link>
        <link name='rear_left_wheel_link'>
          <pose frame=''>-0.31384 -0.321865 0.155008 -3.2e-05 -0.057876 0.022932</pose>
          <velocity>-0.000308 -0.002708 0.007435 -0.030034 0.004414 0.000608</velocity>
          <acceleration>0.561867 -2.02308 8.19729 0.083139 1.46712 2.96868</acceleration>
          <wrench>2.80934 -10.1154 40.9865 0 -0 0</wrench>
        </link>
        <link name='rear_right_wheel_link'>
          <pose frame=''>0.06606 -0.313151 0.155 8e-06 0.273807 0.022934</pose>
          <velocity>5e-06 -0.002754 0.00509 -0.044342 2.2e-05 0.000203</velocity>
          <acceleration>0.718234 -1.96121 12.0814 -1.04914 -0.741171 -3.09312</acceleration>
          <wrench>3.59117 -9.80605 60.4068 0 -0 0</wrench>
        </link>
        <link name='ur5_forearm_link'>
          <pose frame=''>0.41489 -0.039192 0.648984 -2.85059 1.57047 -2.82829</pose>
          <velocity>-0.001909 0.004854 0.006459 -0.028291 -0.023079 -0.01895</velocity>
          <acceleration>-1.80121 0.115344 12.0693 -1.54784 1.22762 -1.47135</acceleration>
          <wrench>-4.09776 0.262407 27.4576 0 -0 0</wrench>
        </link>
        <link name='ur5_shoulder_link'>
          <pose frame=''>-0.009641 -0.064812 0.649152 -7.8e-05 0.000413 0.022287</pose>
          <velocity>0.001922 0.013365 -0.002483 -0.029124 -0.002523 -0.028626</velocity>
          <acceleration>1.92159 13.3647 -2.48308 -0.853523 -0.617417 -0.357819</acceleration>
          <wrench>7.10989 49.4494 -9.1874 0 -0 0</wrench>
        </link>
        <link name='ur5_upper_arm_link'>
          <pose frame=''>-0.012673 0.071004 0.649137 -2.96729 1.57042 -2.94499</pose>
          <velocity>0.000126 0.013185 -0.006508 -0.028723 -0.022835 -0.019022</velocity>
          <acceleration>0.247085 7.85714 -0.29506 1.51836 -0.551849 -1.1137</acceleration>
          <wrench>2.07378 65.945 -2.47643 0 -0 0</wrench>
        </link>
        <link name='ur5_wrist_1_link'>
          <pose frame=''>0.807042 -0.030447 0.648864 -3.14032 -0.003327 -3.11931</pose>
          <velocity>-0.001733 -0.002579 0.015269 -0.009239 -0.019976 -0.024552</velocity>
          <acceleration>-1.73304 -2.57946 15.2695 -2.95572 -1.12622 0.580332</acceleration>
          <wrench>-2.11258 -3.14437 18.6135 0 -0 0</wrench>
        </link>
        <link name='ur5_wrist_2_link'>
          <pose frame=''>0.804969 0.06253 0.648779 -3.14032 -0.003335 -3.11965</pose>
          <velocity>0.000439 -0.002509 0.013346 -0.006604 -0.019892 -0.024598</velocity>
          <acceleration>0.439355 -2.50881 13.3459 -0.320627 -1.0428 0.534606</acceleration>
          <wrench>0.535573 -3.05824 16.2686 0 -0 0</wrench>
        </link>
        <link name='ur5_wrist_3_link'>
          <pose frame=''>0.804657 0.062402 0.55413 -3.14032 -0.003351 -3.11965</pose>
          <velocity>0.002332 -0.003325 0.013337 -0.00703 -0.020033 -0.024486</velocity>
          <acceleration>2.33151 -3.32498 13.3368 -0.74726 -1.18306 0.647005</acceleration>
          <wrench>0.43809 -0.624763 2.50598 0 -0 0</wrench>
        </link>
      </model>
      <model name='unit_box_0'>
        <pose frame=''>2.80492 -0.080131 0.499995 -1e-05 0 0</pose>
        <scale>1 1 1</scale>
        <link name='link'>
          <pose frame=''>2.80492 -0.080131 0.499995 -1e-05 0 0</pose>
          <velocity>0 0 0 0 -0 0</velocity>
          <acceleration>0.004709 0.011055 -9.78158 -0.022108 0.009414 1e-06</acceleration>
          <wrench>0.004709 0.011055 -9.78158 0 -0 0</wrench>
        </link>
      </model>
      <model name='unit_box_1'>
        <pose frame=''>5.55277 2.33485 0.499995 0 1e-05 0</pose>
        <scale>1 1 1</scale>
        <link name='link'>
          <pose frame=''>5.55277 2.33485 0.499995 0 1e-05 0</pose>
          <velocity>0 0 0 0 -0 0</velocity>
          <acceleration>0.010615 -0.006191 -9.78231 0.012424 0.021225 1.8e-05</acceleration>
          <wrench>0.010615 -0.006191 -9.78231 0 -0 0</wrench>
        </link>
      </model>
      <model name='unit_box_2'>
        <pose frame=''>5.45209 -2.77815 0.499995 -1e-05 0 0</pose>
        <scale>1 1 1</scale>
        <link name='link'>
          <pose frame=''>5.45209 -2.77815 0.499995 -1e-05 0 0</pose>
          <velocity>0 0 0 0 -0 0</velocity>
          <acceleration>0.004709 0.011055 -9.78158 -0.022108 0.009414 1e-06</acceleration>
          <wrench>0.004709 0.011055 -9.78158 0 -0 0</wrench>
        </link>
      </model>
      <model name='unit_box_3'>
        <pose frame=''>6.48527 -1.38379 0.5 0 -0 0</pose>
        <scale>1 1 1</scale>
        <link name='link'>
          <pose frame=''>6.48527 -1.38379 0.5 0 -0 0</pose>
          <velocity>0 0 0 0 -0 0</velocity>
          <acceleration>-0.004709 -9.78112 9.78158 0.712677 -0.009414 -4.3e-05</acceleration>
          <wrench>-0.004709 -9.78112 9.78158 0 -0 0</wrench>
        </link>
      </model>
      <light name='sun'>
        <pose frame=''>0 0 10 0 -0 0</pose>
      </light>
    </state>
    <gui fullscreen='0'>
      <camera name='user_camera'>
        <pose frame=''>15.457 1.04024 15.4944 0 0.795643 -3.13099</pose>
        <view_controller>orbit</view_controller>
        <projection_type>perspective</projection_type>
      </camera>
    </gui>
  </world>
</sdf>
